Workbook
Name Slicer_City: #N/A
Name Slicer_Gender: #N/A
Name Slicer_Product: #N/A

Sheet SalesData
A1: Order ID | B1: Customer Name | C1: Age | D1: Gender | E1: Product | F1: Category | G1: Quantity | H1: Price | I1: Order_Date | J1: City
A2: 1001 | B2: Ravi | C2: 50 | D2: M | E2: Phone | F2: Electronics | G2: 0 | H2: 13960 | I2: 2024/01/07 | J2: Hyderabad
A3: 1002 | B3: Sneha | C3: 34 | D3: Female | E3: Jeans | F3: Electronics | G3: 3 | H3: 6733 | I3: 2024-02-05 | J3: Delhi
A4: 1003 | B4: Ajay | D4: F | E4: Shirt | F4: Electronics | G4: 0 | H4: 49737 | I4: 2024/01/22 | J4: Delhi
A5: 1004 | B5: Arun | C5: 40 | D5: male | E5: Tablet | F5: Electronics | G5: 0 | H5: -1000 | I5: 11-01-2024 | J5: Chennai
A6: 1005 | B6: Sneha | C6: 45 | D6: F | E6: Tablet | F6: Clothing | G6: 4 | H6: 0 | I6: 02-02-2024 | J6: Chennai
A7: 1006 | B7: Priya | D7: Female | E7: Tablet | F7: Footwear | G7: 0 | H7: -1000 | I7: 29-01-2024 | J7: Chennai
A8: 1007 | B8: Anita | C8: 32 | D8: male | E8: Tablet | F8: Accessories | G8: 2 | H8: 0 | I8: 2024/01/28 | J8: Chennai
A9: 1008 | B9: Meena | D9: F | E9: Tablet | F9: Footwear | G9: 3 | H9: 2505 | I9: 2024-01-13 | J9: Hyderabad
A10: 1009 | B10: Anita | D10: Male | E10: Shoes | F10: Clothing | G10: 5 | H10: 15644 | I10: 28-02-2024 | J10: Mumbai
A11: 1010 | B11: Anita | C11: 28 | D11: Female | E11: Watch | F11: Electronics | G11: 0 | H11: 5945 | I11: 2024-01-13 | J11: Bangalore
A12: 1011 | B12: Neha | D12: male | E12: Shoes | F12: Electronics | G12: 2 | H12: -1000 | I12: 27-01-2024 | J12: Mumbai
A13: 1012 | B13: Surya | C13: 48 | D13: F | E13: Tablet | F13: Electronics | G13: 2 | H13: -1000 | I13: 2024/02/29 | J13: Chennai
A14: 1013 | B14: Surya | D14: male | E14: Jeans | F14: Clothing | G14: 0 | H14: 0 | I14: 2024/01/30 | J14: Bangalore
A15: 1014 | B15: Arun | D15: M | E15: Laptop | F15: Accessories | G15: 0 | H15: 0 | I15: 2024/01/12 | J15: Delhi
A16: 1015 | B16: Sneha | C16: 48 | D16: M | E16: Phone | F16: Accessories | G16: 0 | H16: -1000 | I16: 30-01-2024 | J16: Hyderabad
A17: 1016 | B17: Ramesh | D17: Female | E17: Bag | F17: Clothing | G17: 2 | H17: 0 | I17: 29-02-2024 | J17: Chennai
A18: 1017 | B18: Manoj | D18: F | E18: Bag | F18: Electronics | G18: 1 | H18: 34599 | I18: 2024-02-01 | J18: Bangalore
A19: 1018 | B19: Divya | C19: 26 | D19: male | E19: Shoes | F19: Accessories | G19: 0 | H19: -1000 | I19: 2024/01/27 | J19: Delhi
A20: 1019 | B20: Priya | D20: M | E20: Jeans | F20: Electronics | G20: 1 | H20: 0 | I20: 2024/02/15 | J20: Mumbai
A21: 1020 | B21: Vikram | D21: F | E21: Jeans | F21: Accessories | G21: 0 | H21: 0 | I21: 2024/02/19 | J21: Delhi
A22: 1021 | B22: Lakshmi | C22: 19 | D22: male | E22: Shirt | F22: Accessories | G22: 0 | H22: 0 | I22: 2024-03-01 | J22: Bangalore
A23: 1022 | B23: Sneha | C23: 28 | D23: F | E23: Watch | F23: Footwear | G23: 0 | H23: 0 | I23: 22-01-2024 | J23: Bangalore
A24: 1023 | B24: Ravi | C24: 43 | D24: M | E24: Jeans | F24: Accessories | G24: 0 | H24: 0 | I24: 19-01-2024 | J24: Mumbai
A25: 1024 | B25: Asha | C25: 46 | D25: F | E25: Laptop | F25: Accessories | G25: 0 | H25: 0 | I25: 02-02-2024 | J25: Delhi
A26: 1025 | B26: Manoj | C26: 45 | D26: F | E26: Jeans | F26: Electronics | G26: 5 | H26: 0 | I26: 27-01-2024 | J26: Delhi
A27: 1026 | B27: Kiran | D27: F | E27: Tablet | F27: Footwear | G27: 1 | H27: 16677 | I27: 18-02-2024 | J27: Mumbai
A28: 1027 | B28: Ravi | C28: 47 | D28: M | E28: Laptop | F28: Electronics | G28: 0 | H28: -1000 | I28: 2024/02/26 | J28: Chennai
A29: 1028 | B29: Manoj | C29: 29 | D29: M | E29: Bag | F29: Footwear | G29: 2 | H29: 49227 | I29: 20-02-2024 | J29: Hyderabad
A30: 1029 | B30: Pooja | C30: 34 | D30: F | E30: Laptop | F30: Clothing | G30: 3 | H30: -1000 | I30: 20-02-2024 | J30: Mumbai
A31: 1030 | B31: Arun | C31: 45 | D31: male | E31: Shirt | F31: Accessories | G31: 3 | H31: 3754 | I31: 2024/01/29 | J31: Bangalore
A32: 1031 | B32: Lakshmi | D32: Female | E32: Tablet | F32: Accessories | G32: 5 | H32: 36400 | I32: 2024-02-13 | J32: Bangalore
A33: 1032 | B33: Pooja | D33: M | E33: Phone | F33: Clothing | G33: 1 | H33: 0 | I33: 2024-01-13 | J33: Hyderabad
A34: 1033 | B34: Manoj | D34: F | E34: Shirt | F34: Electronics | G34: 1 | H34: -1000 | I34: 05-01-2024 | J34: Mumbai
A35: 1034 | B35: Arun | D35: Male | E35: Shirt | F35: Footwear | G35: 0 | H35: 29455 | I35: 2024/02/12 | J35: Bangalore
A36: 1035 | B36: Karthik | D36: male | E36: Watch | F36: Clothing | G36: 5 | H36: -1000 | I36: 2024/02/16 | J36: Delhi
A37: 1036 | B37: Asha | D37: M | E37: Shoes | F37: Footwear | G37: 4 | H37: 0 | I37: 2024/02/03 | J37: Bangalore
A38: 1037 | B38: Vikram | C38: 37 | D38: Male | E38: Bag | F38: Clothing | G38: 2 | H38: 0 | I38: 2024/01/11 | J38: Mumbai
A39: 1038 | B39: Vikram | C39: 40 | D39: F | E39: Phone | F39: Clothing | G39: 0 | H39: 35763 | I39: 2024/01/18 | J39: Mumbai
A40: 1039 | B40: Karthik | C40: 47 | D40: Female | E40: Laptop | F40: Accessories | G40: 5 | H40: 0 | I40: 23-01-2024 | J40: Delhi
...

Sheet Cleandata
A1: Order ID | B1: Customer Name | C1: Age_Category | D1: Age | E1: Age_group | F1: Gender | G1: Product | H1: Category_1 | I1: Quantity | J1: Price | K1: Total_Sales | L1: Order_Date | M1: Sales Category2 | N1: City | O1: Month | P1: Year
A2: 1001 | B2: Ravi | C2: =IF(D2="","Unknown",IF(D2<20,"Teen",IF(D2<40,"Adult","Senior"))) -> Senior | D2: 50 | E2: 31-50 | F2: Male | G2: Phone | H2: Electronics | I2: 2 | J2: 13960 | K2: 27920 | L2: 45298 | M2: =IF(K2>10000,"High",IF(K2>5000,"Medium","Low")) -> High | N2: HYDERABAD | O2: 1 | P2: 2024
A3: 1003 | B3: Ajay | C3: =IF(D3="","Unknown",IF(D3<20,"Teen",IF(D3<40,"Adult","Senior"))) -> Adult | D3: 30 | E3: 21-30 | F3: Female | G3: Shirt | H3: Clothing | I3: 2 | J3: 49737 | K3: 99474 | L3: 45313 | M3: =IF(K3>10000,"High",IF(K3>5000,"Medium","Low")) -> High | N3: DELHI | O3: 1 | P3: 2024
A4: 1004 | B4: Arun | C4: =IF(D4="","Unknown",IF(D4<20,"Teen",IF(D4<40,"Adult","Senior"))) -> Senior | D4: 40 | E4: 31-50 | F4: Male | G4: Tablet | H4: Electronics | I4: 2 | J4: 1000 | K4: 2000 | L4: 45302 | M4: =IF(K4>10000,"High",IF(K4>5000,"Medium","Low")) -> Low | N4: CHENNAI | O4: 1 | P4: 2024
A5: 1006 | B5: Priya | C5: =IF(D5="","Unknown",IF(D5<20,"Teen",IF(D5<40,"Adult","Senior"))) -> Adult | D5: 30 | E5: 21-30 | F5: Female | G5: Tablet | H5: Electronics | I5: 2 | J5: 1000 | K5: 2000 | L5: 45320 | M5: =IF(K5>10000,"High",IF(K5>5000,"Medium","Low")) -> Low | N5: CHENNAI | O5: 1 | P5: 2024
A6: 1007 | B6: Anita | C6: =IF(D6="","Unknown",IF(D6<20,"Teen",IF(D6<40,"Adult","Senior"))) -> Adult | D6: 32 | E6: 31-50 | F6: Male | G6: Tablet | H6: Electronics | I6: 2 | J6: 1000 | K6: 2000 | L6: 45319 | M6: =IF(K6>10000,"High",IF(K6>5000,"Medium","Low")) -> Low | N6: CHENNAI | O6: 1 | P6: 2024
A7: 1008 | B7: Meena | C7: =IF(D7="","Unknown",IF(D7<20,"Teen",IF(D7<40,"Adult","Senior"))) -> Adult | D7: 30 | E7: 21-30 | F7: Female | G7: Tablet | H7: Electronics | I7: 3 | J7: 2505 | K7: 7515 | L7: 45304 | M7: =IF(K7>10000,"High",IF(K7>5000,"Medium","Low")) -> Medium | N7: HYDERABAD | O7: 1 | P7: 2024
A8: 1010 | B8: Anita | C8: =IF(D8="","Unknown",IF(D8<20,"Teen",IF(D8<40,"Adult","Senior"))) -> Adult | D8: 28 | E8: 21-30 | F8: Female | G8: Watch | H8: Accessories | I8: 2 | J8: 5945 | K8: 11890 | L8: 45304 | M8: =IF(K8>10000,"High",IF(K8>5000,"Medium","Low")) -> High | N8: BANGALORE | O8: 1 | P8: 2024
A9: 1011 | B9: Neha | C9: =IF(D9="","Unknown",IF(D9<20,"Teen",IF(D9<40,"Adult","Senior"))) -> Adult | D9: 30 | E9: 21-30 | F9: Male | G9: Shoes | H9: Accessories | I9: 2 | J9: 1000 | K9: 2000 | L9: 45318 | M9: =IF(K9>10000,"High",IF(K9>5000,"Medium","Low")) -> Low | N9: MUMBAI | O9: 1 | P9: 2024
A10: 1013 | B10: Surya | C10: =IF(D10="","Unknown",IF(D10<20,"Teen",IF(D10<40,"Adult","Senior"))) -> Adult | D10: 30 | E10: 21-30 | F10: Male | G10: Jeans | H10: Clothing | I10: 2 | J10: 1000 | K10: 2000 | L10: 45321 | M10: =IF(K10>10000,"High",IF(K10>5000,"Medium","Low")) -> Low | N10: BANGALORE | O10: 1 | P10: 2024
A11: 1014 | B11: Arun | C11: =IF(D11="","Unknown",IF(D11<20,"Teen",IF(D11<40,"Adult","Senior"))) -> Adult | D11: 30 | E11: 21-30 | F11: Male | G11: Laptop | H11: Electronics | I11: 2 | J11: 1000 | K11: 2000 | L11: 45303 | M11: =IF(K11>10000,"High",IF(K11>5000,"Medium","Low")) -> Low | N11: DELHI | O11: 1 | P11: 2024
A12: 1015 | B12: Sneha | C12: =IF(D12="","Unknown",IF(D12<20,"Teen",IF(D12<40,"Adult","Senior"))) -> Senior | D12: 48 | E12: 31-50 | F12: Male | G12: Phone | H12: Electronics | I12: 2 | J12: 1000 | K12: 2000 | L12: 45321 | M12: =IF(K12>10000,"High",IF(K12>5000,"Medium","Low")) -> Low | N12: HYDERABAD | O12: 1 | P12: 2024
A13: 1018 | B13: Divya | C13: =IF(D13="","Unknown",IF(D13<20,"Teen",IF(D13<40,"Adult","Senior"))) -> Adult | D13: 26 | E13: 21-30 | F13: Male | G13: Shoes | H13: Accessories | I13: 2 | J13: 1000 | K13: 2000 | L13: 45318 | M13: =IF(K13>10000,"High",IF(K13>5000,"Medium","Low")) -> Low | N13: DELHI | O13: 1 | P13: 2024
... A1001: 1987 | B1001: Meena | C1001: =IF(D1001="","Unknown",IF(D1001<20,"Teen",IF(D1001<40,"Adult","Senior"))) -> Adult | D1001: 30 | E1001: 21-30 | F1001: Female | G1001: Bag | H1001: Accessories | I1001: 2 | J1001: 1000 | K1001: 2000 | L1001: 45352 | M1001: =IF(K1001>10000,"High",IF(K1001>5000,"Medium","Low")) -> Low | N1001: HYDERABAD | O1001: 3 | P1001: 2024

Sheet Productmapping
A1: Product | B1: Category | G1: Customer Name
A2: Phone | B2: =VLOOKUP(A2,Cleandata!G2:H1001,2,FALSE) -> Electronics | G2: Ravi | H2: =INDEX(Cleandata!D2:D1001,MATCH(G2,G2:G1001,0)) -> 50
A3: Jeans | B3: =VLOOKUP(A3,Cleandata!G3:H1002,2,FALSE) -> Clothing | G3: Sneha | H3: =INDEX(Cleandata!D3:D1002,MATCH(G3,G3:G1002,0)) -> 30
A4: Shirt | B4: =VLOOKUP(A4,Cleandata!G4:H1003,2,FALSE) -> Clothing | G4: Ajay | H4: =INDEX(Cleandata!D4:D1003,MATCH(G4,G4:G1003,0)) -> 40
A5: Tablet | B5: =VLOOKUP(A5,Cleandata!G5:H1004,2,FALSE) -> Electronics | G5: Arun | H5: =INDEX(Cleandata!D5:D1004,MATCH(G5,G5:G1004,0)) -> 30
A6: Tablet | B6: =VLOOKUP(A6,Cleandata!G6:H1005,2,FALSE) -> Electronics | G6: Sneha | H6: =INDEX(Cleandata!D6:D1005,MATCH(G6,G6:G1005,0)) -> 32
A7: Tablet | B7: =VLOOKUP(A7,Cleandata!G7:H1006,2,FALSE) -> Electronics | G7: Priya | H7: =INDEX(Cleandata!D7:D1006,MATCH(G7,G7:G1006,0)) -> 30
A8: Tablet | B8: =VLOOKUP(A8,Cleandata!G8:H1007,2,FALSE) -> Electronics | G8: Anita | H8: =INDEX(Cleandata!D8:D1007,MATCH(G8,G8:G1007,0)) -> 28
A9: Tablet | B9: =VLOOKUP(A9,Cleandata!G9:H1008,2,FALSE) -> Electronics | G9: Meena | H9: =INDEX(Cleandata!D9:D1008,MATCH(G9,G9:G1008,0)) -> 30
A10: Shoes | B10: =VLOOKUP(A10,Cleandata!G10:H1009,2,FALSE) -> Accessories | G10: Anita | H10: =INDEX(Cleandata!D10:D1009,MATCH(G10,G10:G1009,0)) -> 30
A11: Watch | B11: =VLOOKUP(A11,Cleandata!G11:H1010,2,FALSE) -> Accessories | G11: Anita | H11: =INDEX(Cleandata!D11:D1010,MATCH(G11,G11:G1010,0)) -> 30
A12: Shoes | B12: =VLOOKUP(A12,Cleandata!G12:H1011,2,FALSE) -> Accessories | G12: Neha | H12: =INDEX(Cleandata!D12:D1011,MATCH(G12,G12:G1011,0)) -> 48
A13: Tablet | B13: =VLOOKUP(A13,Cleandata!G13:H1012,2,FALSE) -> Electronics | G13: Surya | H13: =INDEX(Cleandata!D13:D1012,MATCH(G13,G13:G1012,0)) -> 26
... A1001: Bag | B1001: =VLOOKUP(A1001,Cleandata!G1001:H2000,2,FALSE) -> Accessories | G1001: Ramesh | H1001: =INDEX(Cleandata!D1001:D2000,MATCH(G1001,G1001:G2000,0)) -> 30

Sheet Pivot Table
A1: Row Labels | B1: Sum of Total_Sales
A2: Bag | B2: 3170080
A3: Jeans | B3: 1963510
A4: Laptop | B4: 2387889
A5: Phone | B5: 2414547
A6: Shirt | B6: 3806599
A7: Shoes | B7: 2634994
A8: Tablet | B8: 3498899
A9: Watch | B9: 2774212
A10: Grand Total | B10: 22650730
A14: Row Labels | B14: Sum of Total_Sales
A15: BANGALORE | B15: 5028522
A16: CHENNAI | B16: 4555826
A17: DELHI | B17: 4513959
A18: HYDERABAD | B18: 3825427
A19: MUMBAI | B19: 4726996
A20: Grand Total | B20: 22650730
A24: Row Labels | B24: Sum of Total_Sales
A25: Female | B25: 8335886
A26: Male | B26: 14314844
A27: Grand Total | B27: 22650730
A32: Row Labels | B32: Sum of Total_Sales
A33: 2024 | B33: 22650730
A34: Jan | B34: 11251547
A35: Feb | B35: 10804703
A36: Mar | B36: 594480
A37: Grand Total | B37: 22650730
A57: Count of Category_1 | B57: Column Labels
A58: Row Labels | B58: Female | C58: Grand Total
A59: Bag | B59: 10 | C59: 10
A60: Jeans | B60: 12 | C60: 12
A61: Laptop | B61: 2 | C61: 2
A62: Phone | B62: 9 | C62: 9
A63: Shirt | B63: 9 | C63: 9
A64: Shoes | B64: 6 | C64: 6
A65: Tablet | B65: 10 | C65: 10
A66: Grand Total | B66: 58 | C66: 58

Sheet DASHBOARD
